Workbook

Sheet README
A1: ServiTech Raw Data Workbook
A2: Purpose | B2: Dummy raw data for Table 8 (before manual walk-in workflow) and Table 9 (after ServiTech-assisted workflow).
A3: Source Alignment | B3: Table 8 follows the uploaded document total of 558 minutes and average of 11.16 minutes. Table 9 follows the attached conversion workbook and adds Uma Patricia Lim as the 50th transaction.
A4: Date Scope for Table 9 | B4: 2026-06-08 to 2026-06-13, with request creation times within 3:00 PM to 5:00 PM.
A5: Final Status Rule | B5: All after-implementation orders are marked DONE.
A6: GCash Flow | B6: PENDING -> APPROVED -> ONGOING -> FOR PICK-UP -> DONE, or PENDING -> APPROVED -> ONGOING -> DONE.
A7: Cash Flow | B7: PENDING -> ONGOING -> FOR PICK-UP -> DONE, or PENDING -> ONGOING -> DONE.
A8: Analytics Coverage | B8: Average queue waiting time, average service processing time, longest waiting request, queue status distribution, average time in each status, status transition history, and completion rate.
A9: Generated File Note | B9: Data is dummy/sample data for documentation, testing, and analytics demonstration only.

Sheet Table9_After_Orders
A1: Transaction No. | B1: Customer Name | C1: Queue ID | D1: Type of Request | E1: Payment Method | F1: GCash Reference No. | G1: Completion Route | H1: Request Created At | I1: Pending At | J1: Approved At | K1: Ongoing At | L1: For Pick-up At | M1: Done At | N1: Final Status | O1: Current Status | P1: Workflow Handling Time (min) | Q1: Queue Waiting Time (min) | R1: Service Processing Time (min) | S1: Pending Status Min | T1: Approved Status Min | U1: Ongoing Status Min | V1: For Pick-up Status Min | W1: Completion Flag | X1: System Status Flow | Y1: Status Transition History | Z1: Notes
A2: 1 | B2: Althea Marielle Santos | C2: P20260608-0001 | D2: Document Printing | E2: GCASH | F2: 9202606000001 | G2: FOR PICK-UP | H2: 46181.65 | I2: 46181.65 | J2: 46181.652 | K2: 46181.654 | L2: 46181.661 | M2: 46181.668 | N2: DONE | O2: DONE | P2: 3 | Q2: 3 | R2: 20 | S2: 3 | T2: 2 | U2: 11 | V2: 9 | W2: 1 | X2: PENDING -> APPROVED -> ONGOING -> FOR PICK-UP -> DONE | Y2: PENDING @ 2026-06-08 03:36:30 PM | APPROVED @ 2026-06-08 03:39:30 PM | ONGOING @ 2026-06-08 03:41:30 PM | FOR PICK-UP @ 2026-06-08 03:52:30 PM | DONE @ 2026-06-08 04:01:30 PM | Z2: Completed order; dummy raw status-timestamp data for analytics.
A3: 2 | B3: Bea Cassandra Tuazon | C3: P20260608-0002 | D3: Document Printing | E3: GCASH | F3: 9202606000002 | G3: FOR PICK-UP | H3: 46181.664 | I3: 46181.664 | J3: 46181.666 | K3: 46181.668 | L3: 46181.677 | M3: 46181.687 | N3: DONE | O3: DONE | P3: 3 | Q3: 3 | R3: 28 | S3: 3 | T3: 3 | U3: 14 | V3: 14 | W3: 1 | X3: PENDING -> APPROVED -> ONGOING -> FOR PICK-UP -> DONE | Y3: PENDING @ 2026-06-08 03:55:30 PM | APPROVED @ 2026-06-08 03:58:30 PM | ONGOING @ 2026-06-08 04:01:30 PM | FOR PICK-UP @ 2026-06-08 04:15:30 PM | DONE @ 2026-06-08 04:29:30 PM | Z3: Completed order; dummy raw status-timestamp data for analytics.
A4: 3 | B4: Camille Ysabel Navarro | C4: P20260608-0003 | D4: Document Printing | E4: CASH | G4: FOR PICK-UP | H4: 46181.69 | I4: 46181.69 | K4: 46181.692 | L4: 46181.704 | M4: 46181.708 | N4: DONE | O4: DONE | P4: 2 | Q4: 2 | R4: 24 | S4: 2 | T4: 0 | U4: 17 | V4: 7 | W4: 1 | X4: PENDING -> ONGOING -> FOR PICK-UP -> DONE | Y4: PENDING @ 2026-06-08 04:34:13 PM | ONGOING @ 2026-06-08 04:36:13 PM | FOR PICK-UP @ 2026-06-08 04:53:13 PM | DONE @ 2026-06-08 05:00:13 PM | Z4: Completed order; dummy raw status-timestamp data for analytics.
A5: 4 | B5: Dianne Rochelle Mercado | C5: P20260608-0004 | D5: Document Printing | E5: GCASH | F5: 9202606000004 | G5: FOR PICK-UP | H5: 46181.695 | I5: 46181.695 | J5: 46181.697 | K5: 46181.698 | L5: 46181.705 | M5: 46181.713 | N5: DONE | O5: DONE | P5: 3 | Q5: 3 | R5: 21 | S5: 3 | T5: 2 | U5: 9 | V5: 12 | W5: 1 | X5: PENDING -> APPROVED -> ONGOING -> FOR PICK-UP -> DONE | Y5: PENDING @ 2026-06-08 04:40:39 PM | APPROVED @ 2026-06-08 04:43:39 PM | ONGOING @ 2026-06-08 04:45:39 PM | FOR PICK-UP @ 2026-06-08 04:54:39 PM | DONE @ 2026-06-08 05:06:39 PM | Z5: Completed order; dummy raw status-timestamp data for analytics.
A6: 5 | B6: Ezekiel Rafael Dizon | C6: P20260608-0005 | D6: Lamination | E6: CASH | G6: FOR PICK-UP | H6: 46181.695 | I6: 46181.695 | K6: 46181.696 | L6: 46181.703 | M6: 46181.706 | N6: DONE | O6: DONE | P6: 2 | Q6: 2 | R6: 14 | S6: 2 | T6: 0 | U6: 9 | V6: 5 | W6: 1 | X6: PENDING -> ONGOING -> FOR PICK-UP -> DONE | Y6: PENDING @ 2026-06-08 04:40:49 PM | ONGOING @ 2026-06-08 04:42:49 PM | FOR PICK-UP @ 2026-06-08 04:51:49 PM | DONE @ 2026-06-08 04:56:49 PM | Z6: Completed order; dummy raw status-timestamp data for analytics.
A7: 6 | B7: Francesca Mae Valerio | C7: P20260608-0006 | D7: Rush ID | E7: GCASH | F7: 9202606000006 | G7: FOR PICK-UP | H7: 46181.701 | I7: 46181.701 | J7: 46181.704 | K7: 46181.705 | L7: 46181.717 | M7: 46181.723 | N7: DONE | O7: DONE | P7: 4 | Q7: 4 | R7: 27 | S7: 4 | T7: 1 | U7: 17 | V7: 10 | W7: 1 | X7: PENDING -> APPROVED -> ONGOING -> FOR PICK-UP -> DONE | Y7: PENDING @ 2026-06-08 04:49:49 PM | APPROVED @ 2026-06-08 04:53:49 PM | ONGOING @ 2026-06-08 04:54:49 PM | FOR PICK-UP @ 2026-06-08 05:11:49 PM | DONE @ 2026-06-08 05:21:49 PM | Z7: Completed order; dummy raw status-timestamp data for analytics.
A8: 7 | B8: Gian Carlo Mendoza | C8: P20260609-0001 | D8: Lamination | E8: CASH | G8: FOR PICK-UP | H8: 46182.642 | I8: 46182.642 | K8: 46182.643 | L8: 46182.647 | M8: 46182.658 | N8: DONE | O8: DONE | P8: 2 | Q8: 2 | R8: 21 | S8: 2 | T8: 0 | U8: 6 | V8: 15 | W8: 1 | X8: PENDING -> ONGOING -> FOR PICK-UP -> DONE | Y8: PENDING @ 2026-06-09 03:24:20 PM | ONGOING @ 2026-06-09 03:26:20 PM | FOR PICK-UP @ 2026-06-09 03:32:20 PM | DONE @ 2026-06-09 03:47:20 PM | Z8: Completed order; dummy raw status-timestamp data for analytics.
A9: 8 | B9: Hannah Elise Bautista | C9: R20260609-0001 | D9: Repair Inquiry / Initial Assessment | E9: CASH | G9: DIRECT DONE | H9: 46182.655 | I9: 46182.655 | K9: 46182.661 | M9: 46182.676 | N9: DONE | O9: DONE | P9: 8 | Q9: 8 | R9: 22 | S9: 8 | T9: 0 | U9: 22 | V9: 0 | W9: 1 | X9: PENDING -> ONGOING -> DONE | Y9: PENDING @ 2026-06-09 03:43:41 PM | ONGOING @ 2026-06-09 03:51:41 PM | DONE @ 2026-06-09 04:13:41 PM | Z9: Completed order; dummy raw status-timestamp data for analytics.
A10: 9 | B10: Ivan Gabriel Soriano | C10: P20260609-0003 | D10: Rush ID | E10: GCASH | F10: 9202606000009 | G10: FOR PICK-UP | H10: 46182.656 | I10: 46182.656 | J10: 46182.659 | K10: 46182.66 | L10: 46182.671 | M10: 46182.68 | N10: DONE | O10: DONE | P10: 4 | Q10: 4 | R10: 29 | S10: 4 | T10: 1 | U10: 16 | V10: 13 | W10: 1 | X10: PENDING -> APPROVED -> ONGOING -> FOR PICK-UP -> DONE | Y10: PENDING @ 2026-06-09 03:44:54 PM | APPROVED @ 2026-06-09 03:48:54 PM | ONGOING @ 2026-06-09 03:49:54 PM | FOR PICK-UP @ 2026-06-09 04:05:54 PM | DONE @ 2026-06-09 04:18:54 PM | Z10: Completed order; dummy raw status-timestamp data for analytics.
A11: 10 | B11: Katrina Denise Uy | C11: P20260609-0004 | D11: Lamination | E11: CASH | G11: FOR PICK-UP | H11: 46182.658 | I11: 46182.658 | K11: 46182.659 | L11: 46182.668 | M11: 46182.672 | N11: DONE | O11: DONE | P11: 2 | Q11: 2 | R11: 18 | S11: 2 | T11: 0 | U11: 12 | V11: 6 | W11: 1 | X11: PENDING -> ONGOING -> FOR PICK-UP -> DONE | Y11: PENDING @ 2026-06-09 03:47:39 PM | ONGOING @ 2026-06-09 03:49:39 PM | FOR PICK-UP @ 2026-06-09 04:01:39 PM | DONE @ 2026-06-09 04:07:39 PM | Z11: Completed order; dummy raw status-timestamp data for analytics.
A12: 11 | B12: Janelle Mikaela Villarama | C12: P20260609-0005 | D12: Lamination | E12: CASH | G12: FOR PICK-UP | H12: 46182.66 | I12: 46182.66 | K12: 46182.662 | L12: 46182.667 | M12: 46182.675 | N12: DONE | O12: DONE | P12: 3 | Q12: 3 | R12: 18 | S12: 3 | T12: 0 | U12: 7 | V12: 11 | W12: 1 | X12: PENDING -> ONGOING -> FOR PICK-UP -> DONE | Y12: PENDING @ 2026-06-09 03:50:19 PM | ONGOING @ 2026-06-09 03:53:19 PM | FOR PICK-UP @ 2026-06-09 04:00:19 PM | DONE @ 2026-06-09 04:11:19 PM | Z12: Completed order; dummy raw status-timestamp data for analytics.
A13: 12 | B13: Mikaela Therese Ramos | C13: P20260609-0006 | D13: Document Printing | E13: GCASH | F13: 9202606000012 | G13: FOR PICK-UP | H13: 46182.664 | I13: 46182.664 | J13: 46182.666 | K13: 46182.667 | L13: 46182.674 | M13: 46182.677 | N13: DONE | O13: DONE | P13: 3 | Q13: 3 | R13: 15 | S13: 3 | T13: 1 | U13: 11 | V13: 4 | W13: 1 | X13: PENDING -> APPROVED -> ONGOING -> FOR PICK-UP -> DONE | Y13: PENDING @ 2026-06-09 03:55:58 PM | APPROVED @ 2026-06-09 03:58:58 PM | ONGOING @ 2026-06-09 03:59:58 PM | FOR PICK-UP @ 2026-06-09 04:10:58 PM | DONE @ 2026-06-09 04:14:58 PM | Z13: Completed order; dummy raw status-timestamp data for analytics.
A14: 13 | B14: Lance Adrian Caballero | C14: P20260609-0007 | D14: Document Printing | E14: GCASH | F14: 9202606000013 | G14: FOR PICK-UP | H14: 46182.672 | I14: 46182.672 | J14: 46182.674 | K14: 46182.675 | L14: 46182.685 | M14: 46182.691 | N14: DONE | O14: DONE | P14: 3 | Q14: 3 | R14: 23 | S14: 3 | T14: 2 | U14: 14 | V14: 9 | W14: 1 | X14: PENDING -> APPROVED -> ONGOING -> FOR PICK-UP -> DONE | Y14: PENDING @ 2026-06-09 04:07:10 PM | APPROVED @ 2026-06-09 04:10:10 PM | ONGOING @ 2026-06-09 04:12:10 PM | FOR PICK-UP @ 2026-06-09 04:26:10 PM | DONE @ 2026-06-09 04:35:10 PM | Z14: Completed order; dummy raw status-timestamp data for analytics.
A15: 14 | B15: Nico Emmanuel Salcedo | C15: P20260609-0008 | D15: Photocopy | E15: CASH | G15: DIRECT DONE | H15: 46182.673 | I15: 46182.673 | K15: 46182.674 | M15: 46182.68 | N15: DONE | O15: DONE | P15: 2 | Q15: 2 | R15: 8 | S15: 2 | T15: 0 | U15: 8 | V15: 0 | W15: 1 | X15: PENDING -> ONGOING -> DONE | Y15: PENDING @ 2026-06-09 04:09:06 PM | ONGOING @ 2026-06-09 04:11:06 PM | DONE @ 2026-06-09 04:19:06 PM | Z15: Completed order; dummy raw status-timestamp data for analytics.
A16: 15 | B16: Olivia Samira Reyes | C16: P20260609-0009 | D16: Photocopy | E16: CASH | G16: FOR PICK-UP | H16: 46182.687 | I16: 46182.687 | K16: 46182.688 | L16: 46182.691 | M16: 46182.696 | N16: DONE | O16: DONE | P16: 2 | Q16: 2 | R16: 11 | S16: 2 | T16: 0 | U16: 4 | V16: 7 | W16: 1 | X16: PENDING -> ONGOING -> FOR PICK-UP -> DONE | Y16: PENDING @ 2026-06-09 04:29:06 PM | ONGOING @ 2026-06-09 04:31:06 PM | FOR PICK-UP @ 2026-06-09 04:35:06 PM | DONE @ 2026-06-09 04:42:06 PM | Z16: Completed order; dummy raw status-timestamp data for analytics.
A17: 16 | B17: Quinn Elijah Manalo | C17: P20260609-0010 | D17: Photocopy | E17: CASH | G17: FOR PICK-UP | H17: 46182.693 | I17: 46182.693 | K17: 46182.694 | L17: 46182.698 | M17: 46182.707 | N17: DONE | O17: DONE | P17: 2 | Q17: 2 | R17: 18 | S17: 2 | T17: 0 | U17: 6 | V17: 12 | W17: 1 | X17: PENDING -> ONGOING -> FOR PICK-UP -> DONE | Y17: PENDING @ 2026-06-09 04:37:29 PM | ONGOING @ 2026-06-09 04:39:29 PM | FOR PICK-UP @ 2026-06-09 04:45:29 PM | DONE @ 2026-06-09 04:57:29 PM | Z17: Completed order; dummy raw status-timestamp data for analytics.
A18: 17 | B18: Paolo Miguel Villanueva | C18: P20260609-0011 | D18: Lamination | E18: CASH | G18: FOR PICK-UP | H18: 46182.695 | I18: 46182.695 | K18: 46182.697 | L18: 46182.705 | M18: 46182.709 | N18: DONE | O18: DONE | P18: 3 | Q18: 3 | R18: 17 | S18: 3 | T18: 0 | U18: 12 | V18: 5 | W18: 1 | X18: PENDING -> ONGOING -> FOR PICK-UP -> DONE | Y18: PENDING @ 2026-06-09 04:40:28 PM | ONGOING @ 2026-06-09 04:43:28 PM | FOR PICK-UP @ 2026-06-09 04:55:28 PM | DONE @ 2026-06-09 05:00:28 PM | Z18: Completed order; dummy raw status-timestamp data for analytics.
A19: 18 | B19: Rhea Dominique Castillo | C19: P20260610-0001 | D19: Lamination | E19: GCASH | F19: 9202606000018 | G19: FOR PICK-UP | H19: 46183.633 | I19: 46183.633 | J19: 46183.635 | K19: 46183.636 | L19: 46183.641 | M19: 46183.648 | N19: DONE | O19: DONE | P19: 3 | Q19: 3 | R19: 17 | S19: 3 | T19: 1 | U19: 7 | V19: 10 | W19: 1 | X19: PENDING -> APPROVED -> ONGOING -> FOR PICK-UP -> DONE | Y19: PENDING @ 2026-06-10 03:11:40 PM | APPROVED @ 2026-06-10 03:14:40 PM | ONGOING @ 2026-06-10 03:15:40 PM | FOR PICK-UP @ 2026-06-10 03:22:40 PM | DONE @ 2026-06-10 03:32:40 PM | Z19: Completed order; dummy raw status-timestamp data for analytics.
A20: 19 | B20: Samantha Louise Alcantara | C20: P20260610-0002 | D20: Rush ID | E20: GCASH | F20: 9202606000019 | G20: FOR PICK-UP | H20: 46183.659 | I20: 46183.659 | J20: 46183.662 | K20: 46183.663 | L20: 46183.674 | M20: 46183.684 | N20: DONE | O20: DONE | P20: 4 | Q20: 4 | R20: 30 | S20: 4 | T20: 2 | U20: 15 | V20: 15 | W20: 1 | X20: PENDING -> APPROVED -> ONGOING -> FOR PICK-UP -> DONE | Y20: PENDING @ 2026-06-10 03:49:10 PM | APPROVED @ 2026-06-10 03:53:10 PM | ONGOING @ 2026-06-10 03:55:10 PM | FOR PICK-UP @ 2026-06-10 04:10:10 PM | DONE @ 2026-06-10 04:25:10 PM | Z20: Completed order; dummy raw status-timestamp data for analytics.
A21: 20 | B21: Theo Nathaniel Garcia | C21: P20260610-0003 | D21: Photocopy | E21: CASH | G21: DIRECT DONE | H21: 46183.661 | I21: 46183.661 | K21: 46183.662 | M21: 46183.667 | N21: DONE | O21: DONE | P21: 2 | Q21: 2 | R21: 8 | S21: 2 | T21: 0 | U21: 8 | V21: 0 | W21: 1 | X21: PENDING -> ONGOING -> DONE | Y21: PENDING @ 2026-06-10 03:51:10 PM | ONGOING @ 2026-06-10 03:53:10 PM | DONE @ 2026-06-10 04:01:10 PM | Z21: Completed order; dummy raw status-timestamp data for analytics.
A22: 21 | B22: Victor Angelo Rosales | C22: P20260610-0004 | D22: Document Printing | E22: GCASH | F22: 9202606000021 | G22: FOR PICK-UP | H22: 46183.678 | I22: 46183.678 | J22: 46183.68 | K22: 46183.68 | L22: 46183.691 | M22: 46183.7 | N22: DONE | O22: DONE | P22: 3 | Q22: 3 | R22: 29 | S22: 3 | T22: 1 | U22: 16 | V22: 13 | W22: 1 | X22: PENDING -> APPROVED -> ONGOING -> FOR PICK-UP -> DONE | Y22: PENDING @ 2026-06-10 04:15:43 PM | APPROVED @ 2026-06-10 04:18:43 PM | ONGOING @ 2026-06-10 04:19:43 PM | FOR PICK-UP @ 2026-06-10 04:35:43 PM | DONE @ 2026-06-10 04:48:43 PM | Z22: Completed order; dummy raw status-timestamp data for analytics.
A23: 22 | B23: Winona Clarisse Tan | C23: P20260610-0005 | D23: Photocopy | E23: CASH | G23: DIRECT DONE | H23: 46183.685 | I23: 46183.685 | K23: 46183.686 | M23: 46183.69 | N23: DONE | O23: DONE | P23: 2 | Q23: 2 | R23: 6 | S23: 2 | T23: 0 | U23: 6 | V23: 0 | W23: 1 | X23: PENDING -> ONGOING -> DONE | Y23: PENDING @ 2026-06-10 04:26:07 PM | ONGOING @ 2026-06-10 04:28:07 PM | DONE @ 2026-06-10 04:34:07 PM | Z23: Completed order; dummy raw status-timestamp data for analytics.
A24: 23 | B24: Xavier Luis Enriquez | C24: P20260610-0006 | D24: Document Printing | E24: GCASH | F24: 9202606000023 | G24: FOR PICK-UP | H24: 46183.699 | I24: 46183.699 | J24: 46183.701 | K24: 46183.703 | L24: 46183.711 | M24: 46183.718 | N24: DONE | O24: DONE | P24: 3 | Q24: 3 | R24: 22 | S24: 3 | T24: 3 | U24: 11 | V24: 11 | W24: 1 | X24: PENDING -> APPROVED -> ONGOING -> FOR PICK-UP -> DONE | Y24: PENDING @ 2026-06-10 04:46:27 PM | APPROVED @ 2026-06-10 04:49:27 PM | ONGOING @ 2026-06-10 04:52:27 PM | FOR PICK-UP @ 2026-06-10 05:03:27 PM | DONE @ 2026-06-10 05:14:27 PM | Z24: Completed order; dummy raw status-timestamp data for analytics.
A25: 24 | B25: Yna Gabrielle Morales | C25: P20260611-0001 | D25: Lamination | E25: CASH | G25: FOR PICK-UP | H25: 46184.637 | I25: 46184.637 | K25: 46184.639 | L25: 46184.647 | M25: 46184.65 | N25: DONE | O25: DONE | P25: 2 | Q25: 2 | R25: 16 | S25: 2 | T25: 0 | U25: 12 | V25: 4 | W25: 1 | X25: PENDING -> ONGOING -> FOR PICK-UP -> DONE | Y25: PENDING @ 2026-06-11 03:17:49 PM | ONGOING @ 2026-06-11 03:19:49 PM | FOR PICK-UP @ 2026-06-11 03:31:49 PM | DONE @ 2026-06-11 03:35:49 PM | Z25: Completed order; dummy raw status-timestamp data for analytics.
A26: 25 | B26: Zachary Sean De Leon | C26: P20260611-0002 | D26: Document Printing | E26: GCASH | F26: 9202606000025 | G26: FOR PICK-UP | H26: 46184.641 | I26: 46184.641 | J26: 46184.642 | K26: 46184.644 | L26: 46184.656 | M26: 46184.662 | N26: DONE | O26: DONE | P26: 2 | Q26: 2 | R26: 26 | S26: 2 | T26: 2 | U26: 17 | V26: 9 | W26: 1 | X26: PENDING -> APPROVED -> ONGOING -> FOR PICK-UP -> DONE | Y26: PENDING @ 2026-06-11 03:23:06 PM | APPROVED @ 2026-06-11 03:25:06 PM | ONGOING @ 2026-06-11 03:27:06 PM | FOR PICK-UP @ 2026-06-11 03:44:06 PM | DONE @ 2026-06-11 03:53:06 PM | Z26: Completed order; dummy raw status-timestamp data for analytics.
A27: 26 | B27: Aira Nicole Baltazar | C27: P20260611-0003 | D27: Lamination | E27: CASH | G27: FOR PICK-UP | H27: 46184.652 | I27: 46184.652 | K27: 46184.654 | L27: 46184.66 | M27: 46184.669 | N27: DONE | O27: DONE | P27: 2 | Q27: 2 | R27: 23 | S27: 2 | T27: 0 | U27: 9 | V27: 14 | W27: 1 | X27: PENDING -> ONGOING -> FOR PICK-UP -> DONE | Y27: PENDING @ 2026-06-11 03:39:04 PM | ONGOING @ 2026-06-11 03:41:04 PM | FOR PICK-UP @ 2026-06-11 03:50:04 PM | DONE @ 2026-06-11 04:04:04 PM | Z27: Completed order; dummy raw status-timestamp data for analytics.
A28: 27 | B28: Bryan Mateo Evangelista | C28: P20260611-0004 | D28: Lamination | E28: CASH | G28: FOR PICK-UP | H28: 46184.668 | I28: 46184.668 | K28: 46184.67 | L28: 46184.678 | M28: 46184.683 | N28: DONE | O28: DONE | P28: 3 | Q28: 3 | R28: 18 | S28: 3 | T28: 0 | U28: 11 | V28: 7 | W28: 1 | X28: PENDING -> ONGOING -> FOR PICK-UP -> DONE | Y28: PENDING @ 2026-06-11 04:02:29 PM | ONGOING @ 2026-06-11 04:05:29 PM | FOR PICK-UP @ 2026-06-11 04:16:29 PM | DONE @ 2026-06-11 04:23:29 PM | Z28: Completed order; dummy raw status-timestamp data for analytics.
A29: 28 | B29: Cheska Noelle Ignacio | C29: P20260611-0005 | D29: Document Printing | E29: GCASH | F29: 9202606000028 | G29: FOR PICK-UP | H29: 46184.674 | I29: 46184.674 | J29: 46184.676 | K29: 46184.678 | L29: 46184.688 | M29: 46184.697 | N29: DONE | O29: DONE | P29: 3 | Q29: 3 | R29: 27 | S29: 3 | T29: 2 | U29: 15 | V29: 12 | W29: 1 | X29: PENDING -> APPROVED -> ONGOING -> FOR PICK-UP -> DONE | Y29: PENDING @ 2026-06-11 04:11:05 PM | APPROVED @ 2026-06-11 04:14:05 PM | ONGOING @ 2026-06-11 04:16:05 PM | FOR PICK-UP @ 2026-06-11 04:31:05 PM | DONE @ 2026-06-11 04:43:05 PM | Z29: Completed order; dummy raw status-timestamp data for analytics.
A30: 29 | B30: Daryl Joaquin Ferrer | C30: P20260611-0006 | D30: Document Printing | E30: CASH | G30: FOR PICK-UP | H30: 46184.68 | I30: 46184.68 | K30: 46184.682 | L30: 46184.694 | M30: 46184.698 | N30: DONE | O30: DONE | P30: 3 | Q30: 3 | R30: 23 | S30: 3 | T30: 0 | U30: 18 | V30: 5 | W30: 1 | X30: PENDING -> ONGOING -> FOR PICK-UP -> DONE | Y30: PENDING @ 2026-06-11 04:19:00 PM | ONGOING @ 2026-06-11 04:22:00 PM | FOR PICK-UP @ 2026-06-11 04:40:00 PM | DONE @ 2026-06-11 04:45:00 PM | Z30: Completed order; dummy raw status-timestamp data for analytics.
A31: 30 | B31: Elaine Sophia Magtibay | C31: P20260611-0007 | D31: Document Printing | E31: GCASH | F31: 9202606000030 | G31: FOR PICK-UP | H31: 46184.68 | I31: 46184.68 | J31: 46184.683 | K31: 46184.683 | L31: 46184.69 | M31: 46184.697 | N31: DONE | O31: DONE | P31: 3 | Q31: 3 | R31: 20 | S31: 3 | T31: 1 | U31: 10 | V31: 10 | W31: 1 | X31: PENDING -> APPROVED -> ONGOING -> FOR PICK-UP -> DONE | Y31: PENDING @ 2026-06-11 04:19:54 PM | APPROVED @ 2026-06-11 04:22:54 PM | ONGOING @ 2026-06-11 04:23:54 PM | FOR PICK-UP @ 2026-06-11 04:33:54 PM | DONE @ 2026-06-11 04:43:54 PM | Z31: Completed order; dummy raw status-timestamp data for analytics.
A32: 31 | B32: Harvey Sebastian Aquino | C32: P20260611-0008 | D32: Rush ID | E32: GCASH | F32: 9202606000031 | G32: FOR PICK-UP | H32: 46184.691 | I32: 46184.691 | J32: 46184.694 | K32: 46184.695 | L32: 46184.708 | M32: 46184.718 | N32: DONE | O32: DONE | P32: 4 | Q32: 4 | R32: 33 | S32: 4 | T32: 2 | U32: 18 | V32: 15 | W32: 1 | X32: PENDING -> APPROVED -> ONGOING -> FOR PICK-UP -> DONE | Y32: PENDING @ 2026-06-11 04:35:10 PM | APPROVED @ 2026-06-11 04:39:10 PM | ONGOING @ 2026-06-11 04:41:10 PM | FOR PICK-UP @ 2026-06-11 04:59:10 PM | DONE @ 2026-06-11 05:14:10 PM | Z32: Completed order; dummy raw status-timestamp data for analytics.
A33: 32 | B33: Jasper Lorenzo Cruzado | C33: P20260611-0009 | D33: Photocopy | E33: CASH | G33: DIRECT DONE | H33: 46184.693 | I33: 46184.693 | K33: 46184.694 | M33: 46184.7 | N33: DONE | O33: DONE | P33: 2 | Q33: 2 | R33: 8 | S33: 2 | T33: 0 | U33: 8 | V33: 0 | W33: 1 | X33: PENDING -> ONGOING -> DONE | Y33: PENDING @ 2026-06-11 04:37:38 PM | ONGOING @ 2026-06-11 04:39:38 PM | DONE @ 2026-06-11 04:47:38 PM | Z33: Completed order; dummy raw status-timestamp data for analytics.
A34: 33 | B34: Francine Alexa Mendoza | C34: P20260611-0010 | D34: Document Printing | E34: CASH | G34: FOR PICK-UP | H34: 46184.694 | I34: 46184.694 | K34: 46184.695 | L34: 46184.701 | M34: 46184.71 | N34: DONE | O34: DONE | P34: 2 | Q34: 2 | R34: 21 | S34: 2 | T34: 0 | U34: 8 | V34: 13 | W34: 1 | X34: PENDING -> ONGOING -> FOR PICK-UP -> DONE | Y34: PENDING @ 2026-06-11 04:38:48 PM | ONGOING @ 2026-06-11 04:40:48 PM | FOR PICK-UP @ 2026-06-11 04:48:48 PM | DONE @ 2026-06-11 05:01:48 PM | Z34: Completed order; dummy raw status-timestamp data for analytics.
A35: 34 | B35: Ivy Marjorie Paredes | C35: P20260611-0011 | D35: Rush ID | E35: GCASH | F35: 9202606000034 | G35: FOR PICK-UP | H35: 46184.7 | I35: 46184.7 | J35: 46184.703 | K35: 46184.704 | L35: 46184.716 | M35: 46184.72 | N35: DONE | O35: DONE | P35: 4 | Q35: 4 | R35: 23 | S35: 4 | T35: 2 | U35: 17 | V35: 6 | W35: 1 | X35: PENDING -> APPROVED -> ONGOING -> FOR PICK-UP -> DONE | Y35: PENDING @ 2026-06-11 04:48:06 PM | APPROVED @ 2026-06-11 04:52:06 PM | ONGOING @ 2026-06-11 04:54:06 PM | FOR PICK-UP @ 2026-06-11 05:11:06 PM | DONE @ 2026-06-11 05:17:06 PM | Z35: Completed order; dummy raw status-timestamp data for analytics.
A36: 35 | B36: Kyla Bernadette Flores | C36: P20260611-0012 | D36: Lamination | E36: CASH | G36: FOR PICK-UP | H36: 46184.701 | I36: 46184.701 | K36: 46184.703 | L36: 46184.707 | M36: 46184.715 | N36: DONE | O36: DONE | P36: 2 | Q36: 2 | R36: 17 | S36: 2 | T36: 0 | U36: 6 | V36: 11 | W36: 1 | X36: PENDING -> ONGOING -> FOR PICK-UP -> DONE | Y36: PENDING @ 2026-06-11 04:50:06 PM | ONGOING @ 2026-06-11 04:52:06 PM | FOR PICK-UP @ 2026-06-11 04:58:06 PM | DONE @ 2026-06-11 05:09:06 PM | Z36: Completed order; dummy raw status-timestamp data for analytics.
A37: 36 | B37: Leandro Marcus Santiago | C37: P20260611-0013 | D37: Rush ID | E37: GCASH | F37: 9202606000036 | G37: FOR PICK-UP | H37: 46184.701 | I37: 46184.701 | J37: 46184.704 | K37: 46184.705 | L37: 46184.715 | M37: 46184.717 | N37: DONE | O37: DONE | P37: 4 | Q37: 4 | R37: 18 | S37: 4 | T37: 1 | U37: 14 | V37: 4 | W37: 1 | X37: PENDING -> APPROVED -> ONGOING -> FOR PICK-UP -> DONE | Y37: PENDING @ 2026-06-11 04:50:06 PM | APPROVED @ 2026-06-11 04:54:06 PM | ONGOING @ 2026-06-11 04:55:06 PM | FOR PICK-UP @ 2026-06-11 05:09:06 PM | DONE @ 2026-06-11 05:13:06 PM | Z37: Completed order; dummy raw status-timestamp data for analytics.
A38: 37 | B38: Mara Isabelle Angeles | C38: P20260612-0001 | D38: Photocopy | E38: CASH | G38: DIRECT DONE | H38: 46185.636 | I38: 46185.636 | K38: 46185.637 | M38: 46185.641 | N38: DONE | O38: DONE | P38: 2 | Q38: 2 | R38: 6 | S38: 2 | T38: 0 | U38: 6 | V38: 0 | W38: 1 | X38: PENDING -> ONGOING -> DONE | Y38: PENDING @ 2026-06-12 03:15:37 PM | ONGOING @ 2026-06-12 03:17:37 PM | DONE @ 2026-06-12 03:23:37 PM | Z38: Completed order; dummy raw status-timestamp data for analytics.
A39: 38 | B39: Noah Vincent Domingo | C39: P20260612-0002 | D39: Photocopy | E39: CASH | G39: FOR PICK-UP | H39: 46185.643 | I39: 46185.643 | K39: 46185.644 | L39: 46185.65 | M39: 46185.66 | N39: DONE | O39: DONE | P39: 2 | Q39: 2 | R39: 22 | S39: 2 | T39: 0 | U39: 8 | V39: 14 | W39: 1 | X39: PENDING -> ONGOING -> FOR PICK-UP -> DONE | Y39: PENDING @ 2026-06-12 03:26:02 PM | ONGOING @ 2026-06-12 03:28:02 PM | FOR PICK-UP @ 2026-06-12 03:36:02 PM | DONE @ 2026-06-12 03:50:02 PM | Z39: Completed order; dummy raw status-timestamp data for analytics.
A40: 39 | B40: Patricia Anika Estrella | C40: P20260612-0003 | D40: Document Printing | E40: GCASH | F40: 9202606000039 | G40: FOR PICK-UP | H40: 46185.653 | I40: 46185.653 | J40: 46185.655 | K40: 46185.656 | L40: 46185.666 | M40: 46185.671 | N40: DONE | O40: DONE | P40: 3 | Q40: 3 | R40: 22 | S40: 3 | T40: 1 | U40: 15 | V40: 7 | W40: 1 | X40: PENDING -> APPROVED -> ONGOING -> FOR PICK-UP -> DONE | Y40: PENDING @ 2026-06-12 03:40:31 PM | APPROVED @ 2026-06-12 03:43:31 PM | ONGOING @ 2026-06-12 03:44:31 PM | FOR PICK-UP @ 2026-06-12 03:59:31 PM | DONE @ 2026-06-12 04:06:31 PM | Z40: Completed order; dummy raw status-timestamp data for analytics.
...

Sheet Table9_Status_Events
A1: Transaction No. | B1: Queue ID | C1: Customer Name | D1: Type of Request | E1: Payment Method | F1: Transition No. | G1: Status | H1: Entered At | I1: Exited At | J1: Duration Min | K1: Next Status | L1: Remarks
A2: 1 | B2: P20260608-0001 | C2: Althea Marielle Santos | D2: Document Printing | E2: GCASH | F2: 1 | G2: PENDING | H2: 46181.65 | I2: 46181.652 | J2: 3 | K2: APPROVED | L2: Request joined the queue.
A3: 1 | B3: P20260608-0001 | C3: Althea Marielle Santos | D3: Document Printing | E3: GCASH | F3: 2 | G3: APPROVED | H3: 46181.652 | I3: 46181.654 | J3: 2 | K3: ONGOING | L3: GCash payment/reference approved before processing.
A4: 1 | B4: P20260608-0001 | C4: Althea Marielle Santos | D4: Document Printing | E4: GCASH | F4: 3 | G4: ONGOING | H4: 46181.654 | I4: 46181.661 | J4: 11 | K4: FOR PICK-UP | L4: Service request was being processed.
A5: 1 | B5: P20260608-0001 | C5: Althea Marielle Santos | D5: Document Printing | E5: GCASH | F5: 4 | G5: FOR PICK-UP | H5: 46181.661 | I5: 46181.668 | J5: 9 | K5: DONE | L5: Request was ready and later marked done after pickup.
A6: 1 | B6: P20260608-0001 | C6: Althea Marielle Santos | D6: Document Printing | E6: GCASH | F6: 5 | G6: DONE | H6: 46181.668 | J6: 0 | L6: Final status; order completed.
A7: 2 | B7: P20260608-0002 | C7: Bea Cassandra Tuazon | D7: Document Printing | E7: GCASH | F7: 1 | G7: PENDING | H7: 46181.664 | I7: 46181.666 | J7: 3 | K7: APPROVED | L7: Request joined the queue.
A8: 2 | B8: P20260608-0002 | C8: Bea Cassandra Tuazon | D8: Document Printing | E8: GCASH | F8: 2 | G8: APPROVED | H8: 46181.666 | I8: 46181.668 | J8: 3 | K8: ONGOING | L8: GCash payment/reference approved before processing.
A9: 2 | B9: P20260608-0002 | C9: Bea Cassandra Tuazon | D9: Document Printing | E9: GCASH | F9: 3 | G9: ONGOING | H9: 46181.668 | I9: 46181.677 | J9: 14 | K9: FOR PICK-UP | L9: Service request was being processed.
A10: 2 | B10: P20260608-0002 | C10: Bea Cassandra Tuazon | D10: Document Printing | E10: GCASH | F10: 4 | G10: FOR PICK-UP | H10: 46181.677 | I10: 46181.687 | J10: 14 | K10: DONE | L10: Request was ready and later marked done after pickup.
A11: 2 | B11: P20260608-0002 | C11: Bea Cassandra Tuazon | D11: Document Printing | E11: GCASH | F11: 5 | G11: DONE | H11: 46181.687 | J11: 0 | L11: Final status; order completed.
A12: 3 | B12: P20260608-0003 | C12: Camille Ysabel Navarro | D12: Document Printing | E12: CASH | F12: 1 | G12: PENDING | H12: 46181.69 | I12: 46181.692 | J12: 2 | K12: ONGOING | L12: Request joined the queue.
A13: 3 | B13: P20260608-0003 | C13: Camille Ysabel Navarro | D13: Document Printing | E13: CASH | F13: 2 | G13: ONGOING | H13: 46181.692 | I13: 46181.704 | J13: 17 | K13: FOR PICK-UP | L13: Service request was being processed.
A14: 3 | B14: P20260608-0003 | C14: Camille Ysabel Navarro | D14: Document Printing | E14: CASH | F14: 3 | G14: FOR PICK-UP | H14: 46181.704 | I14: 46181.708 | J14: 7 | K14: DONE | L14: Request was ready and later marked done after pickup.
A15: 3 | B15: P20260608-0003 | C15: Camille Ysabel Navarro | D15: Document Printing | E15: CASH | F15: 4 | G15: DONE | H15: 46181.708 | J15: 0 | L15: Final status; order completed.
A16: 4 | B16: P20260608-0004 | C16: Dianne Rochelle Mercado | D16: Document Printing | E16: GCASH | F16: 1 | G16: PENDING | H16: 46181.695 | I16: 46181.697 | J16: 3 | K16: APPROVED | L16: Request joined the queue.
A17: 4 | B17: P20260608-0004 | C17: Dianne Rochelle Mercado | D17: Document Printing | E17: GCASH | F17: 2 | G17: APPROVED | H17: 46181.697 | I17: 46181.698 | J17: 2 | K17: ONGOING | L17: GCash payment/reference approved before processing.
A18: 4 | B18: P20260608-0004 | C18: Dianne Rochelle Mercado | D18: Document Printing | E18: GCASH | F18: 3 | G18: ONGOING | H18: 46181.698 | I18: 46181.705 | J18: 9 | K18: FOR PICK-UP | L18: Service request was being processed.
A19: 4 | B19: P20260608-0004 | C19: Dianne Rochelle Mercado | D19: Document Printing | E19: GCASH | F19: 4 | G19: FOR PICK-UP | H19: 46181.705 | I19: 46181.713 | J19: 12 | K19: DONE | L19: Request was ready and later marked done after pickup.
A20: 4 | B20: P20260608-0004 | C20: Dianne Rochelle Mercado | D20: Document Printing | E20: GCASH | F20: 5 | G20: DONE | H20: 46181.713 | J20: 0 | L20: Final status; order completed.
A21: 5 | B21: P20260608-0005 | C21: Ezekiel Rafael Dizon | D21: Lamination | E21: CASH | F21: 1 | G21: PENDING | H21: 46181.695 | I21: 46181.696 | J21: 2 | K21: ONGOING | L21: Request joined the queue.
A22: 5 | B22: P20260608-0005 | C22: Ezekiel Rafael Dizon | D22: Lamination | E22: CASH | F22: 2 | G22: ONGOING | H22: 46181.696 | I22: 46181.703 | J22: 9 | K22: FOR PICK-UP | L22: Service request was being processed.
A23: 5 | B23: P20260608-0005 | C23: Ezekiel Rafael Dizon | D23: Lamination | E23: CASH | F23: 3 | G23: FOR PICK-UP | H23: 46181.703 | I23: 46181.706 | J23: 5 | K23: DONE | L23: Request was ready and later marked done after pickup.
A24: 5 | B24: P20260608-0005 | C24: Ezekiel Rafael Dizon | D24: Lamination | E24: CASH | F24: 4 | G24: DONE | H24: 46181.706 | J24: 0 | L24: Final status; order completed.
A25: 6 | B25: P20260608-0006 | C25: Francesca Mae Valerio | D25: Rush ID | E25: GCASH | F25: 1 | G25: PENDING | H25: 46181.701 | I25: 46181.704 | J25: 4 | K25: APPROVED | L25: Request joined the queue.
A26: 6 | B26: P20260608-0006 | C26: Francesca Mae Valerio | D26: Rush ID | E26: GCASH | F26: 2 | G26: APPROVED | H26: 46181.704 | I26: 46181.705 | J26: 1 | K26: ONGOING | L26: GCash payment/reference approved before processing.
A27: 6 | B27: P20260608-0006 | C27: Francesca Mae Valerio | D27: Rush ID | E27: GCASH | F27: 3 | G27: ONGOING | H27: 46181.705 | I27: 46181.717 | J27: 17 | K27: FOR PICK-UP | L27: Service request was being processed.
A28: 6 | B28: P20260608-0006 | C28: Francesca Mae Valerio | D28: Rush ID | E28: GCASH | F28: 4 | G28: FOR PICK-UP | H28: 46181.717 | I28: 46181.723 | J28: 10 | K28: DONE | L28: Request was ready and later marked done after pickup.
A29: 6 | B29: P20260608-0006 | C29: Francesca Mae Valerio | D29: Rush ID | E29: GCASH | F29: 5 | G29: DONE | H29: 46181.723 | J29: 0 | L29: Final status; order completed.
A30: 7 | B30: P20260609-0001 | C30: Gian Carlo Mendoza | D30: Lamination | E30: CASH | F30: 1 | G30: PENDING | H30: 46182.642 | I30: 46182.643 | J30: 2 | K30: ONGOING | L30: Request joined the queue.
A31: 7 | B31: P20260609-0001 | C31: Gian Carlo Mendoza | D31: Lamination | E31: CASH | F31: 2 | G31: ONGOING | H31: 46182.643 | I31: 46182.647 | J31: 6 | K31: FOR PICK-UP | L31: Service request was being processed.
A32: 7 | B32: P20260609-0001 | C32: Gian Carlo Mendoza | D32: Lamination | E32: CASH | F32: 3 | G32: FOR PICK-UP | H32: 46182.647 | I32: 46182.658 | J32: 15 | K32: DONE | L32: Request was ready and later marked done after pickup.
A33: 7 | B33: P20260609-0001 | C33: Gian Carlo Mendoza | D33: Lamination | E33: CASH | F33: 4 | G33: DONE | H33: 46182.658 | J33: 0 | L33: Final status; order completed.
A34: 8 | B34: R20260609-0001 | C34: Hannah Elise Bautista | D34: Repair Inquiry / Initial Assessment | E34: CASH | F34: 1 | G34: PENDING | H34: 46182.655 | I34: 46182.661 | J34: 8 | K34: ONGOING | L34: Request joined the queue.
A35: 8 | B35: R20260609-0001 | C35: Hannah Elise Bautista | D35: Repair Inquiry / Initial Assessment | E35: CASH | F35: 2 | G35: ONGOING | H35: 46182.661 | I35: 46182.676 | J35: 22 | K35: DONE | L35: Service request was being processed.
A36: 8 | B36: R20260609-0001 | C36: Hannah Elise Bautista | D36: Repair Inquiry / Initial Assessment | E36: CASH | F36: 3 | G36: DONE | H36: 46182.676 | J36: 0 | L36: Final status; order completed.
A37: 9 | B37: P20260609-0003 | C37: Ivan Gabriel Soriano | D37: Rush ID | E37: GCASH | F37: 1 | G37: PENDING | H37: 46182.656 | I37: 46182.659 | J37: 4 | K37: APPROVED | L37: Request joined the queue.
A38: 9 | B38: P20260609-0003 | C38: Ivan Gabriel Soriano | D38: Rush ID | E38: GCASH | F38: 2 | G38: APPROVED | H38: 46182.659 | I38: 46182.66 | J38: 1 | K38: ONGOING | L38: GCash payment/reference approved before processing.
A39: 9 | B39: P20260609-0003 | C39: Ivan Gabriel Soriano | D39: Rush ID | E39: GCASH | F39: 3 | G39: ONGOING | H39: 46182.66 | I39: 46182.671 | J39: 16 | K39: FOR PICK-UP | L39: Service request was being processed.
A40: 9 | B40: P20260609-0003 | C40: Ivan Gabriel Soriano | D40: Rush ID | E40: GCASH | F40: 4 | G40: FOR PICK-UP | H40: 46182.671 | I40: 46182.68 | J40: 13 | K40: DONE | L40: Request was ready and later marked done after pickup.
...

Sheet Analytics_Summary
A1: ServiTech Analytics-Ready Summary
A2: Metric | B2: Formula / Result
A3: Average queue waiting time (minutes) | B3: =AVERAGE(Table9_After_Orders!Q2:Q51) -> 2.92
A4: Average service processing time (minutes) | B4: =AVERAGE(Table9_After_Orders!R2:R51) -> 20
A5: Longest waiting request - Queue ID | B5: =INDEX(Table9_After_Orders!C2:C51,MATCH(MAX(Table9_After_Orders!Q2:Q51),Table9_After_Orders!Q2:Q51,0)) -> R20260609-0001
A6: Longest waiting request - Customer | B6: =INDEX(Table9_After_Orders!B2:B51,MATCH(MAX(Table9_After_Orders!Q2:Q51),Table9_After_Orders!Q2:Q51,0)) -> Hannah Elise Bautista
A7: Longest waiting request - Minutes | B7: =MAX(Table9_After_Orders!Q2:Q51) -> 8
A8: Completion rate | B8: =COUNTIF(Table9_After_Orders!N2:N51,"DONE")/COUNTA(Table9_After_Orders!N2:N51) -> 1
A9: Total after-implementation transactions | B9: =COUNTA(Table9_After_Orders!A2:A51) -> 50
A10: Total status transition events | B10: =COUNTA(Table9_Status_Events!A2:A500) -> 214
A12: Final Queue Status Distribution
A13: Status | B13: Count
A14: PENDING | B14: =COUNTIF(Table9_After_Orders!N2:N51,"PENDING") -> 0
A15: APPROVED | B15: =COUNTIF(Table9_After_Orders!N2:N51,"APPROVED") -> 0
A16: ONGOING | B16: =COUNTIF(Table9_After_Orders!N2:N51,"ONGOING") -> 0
A17: FOR PICK-UP | B17: =COUNTIF(Table9_After_Orders!N2:N51,"FOR PICK-UP") -> 0
A18: DONE | B18: =COUNTIF(Table9_After_Orders!N2:N51,"DONE") -> 50
A19: CANCELLED | B19: =COUNTIF(Table9_After_Orders!N2:N51,"CANCELLED") -> 0
A21: Average Time Spent in Each Status
A22: Status | B22: Average Minutes
A23: PENDING | B23: =AVERAGEIF(Table9_Status_Events!G2:G500,"PENDING",Table9_Status_Events!J2:J500) -> 2.92
A24: APPROVED | B24: =AVERAGEIF(Table9_Status_Events!G2:G500,"APPROVED",Table9_Status_Events!J2:J500) -> 1.8695652
A25: ONGOING | B25: =AVERAGEIF(Table9_Status_Events!G2:G500,"ONGOING",Table9_Status_Events!J2:J500) -> 12.06
A26: FOR PICK-UP | B26: =AVERAGEIF(Table9_Status_Events!G2:G500,"FOR PICK-UP",Table9_Status_Events!J2:J500) -> 9.6829268
A27: DONE | B27: =AVERAGEIF(Table9_Status_Events!G2:G500,"DONE",Table9_Status_Events!J2:J500) -> 0
A28: CANCELLED | B28: =IFERROR(AVERAGEIF(Table9_Status_Events!G2:G500,"CANCELLED",Table9_Status_Events!J2:J500),0) -> 0
A30: Status Transition Event Distribution
A31: Status | B31: Event Count
A32: PENDING | B32: =COUNTIF(Table9_Status_Events!G2:G500,"PENDING") -> 50
A33: APPROVED | B33: =COUNTIF(Table9_Status_Events!G2:G500,"APPROVED") -> 23
A34: ONGOING | B34: =COUNTIF(Table9_Status_Events!G2:G500,"ONGOING") -> 50
A35: FOR PICK-UP | B35: =COUNTIF(Table9_Status_Events!G2:G500,"FOR PICK-UP") -> 41
A36: DONE | B36: =COUNTIF(Table9_Status_Events!G2:G500,"DONE") -> 50
A37: CANCELLED | B37: =COUNTIF(Table9_Status_Events!G2:G500,"CANCELLED") -> 0

Sheet Data_Dictionary
A1: Sheet | B1: Column / Metric | C1: Definition
A2: Table8_Before_Raw | B2: Workflow Handling Time (min) | C2: Manual initial handling duration observed before ServiTech implementation.
A3: Table9_After_Orders | B3: Workflow Handling Time (min) | C3: Time from joining the queue to being approved for GCash or started for Cash.
A4: Table9_After_Orders | B4: Queue Waiting Time (min) | C4: Same analytics definition: Request Created At to Approved At for GCash, or Request Created At to Ongoing At for Cash.
A5: Table9_After_Orders | B5: Service Processing Time (min) | C5: Time from Ongoing At to Done At.
A6: Table9_After_Orders | B6: Pending Status Min | C6: Time spent in PENDING status.
A7: Table9_After_Orders | B7: Approved Status Min | C7: Time spent in APPROVED status; applies only to GCash orders.
A8: Table9_After_Orders | B8: Ongoing Status Min | C8: Time spent in ONGOING status until FOR PICK-UP or DONE.
A9: Table9_After_Orders | B9: For Pick-up Status Min | C9: Time spent in FOR PICK-UP status before DONE.
A10: Table9_Status_Events | B10: Duration Min | C10: Time spent in each status transition event.
A11: Analytics_Summary | B11: Completion Rate | C11: Completed orders divided by all after-implementation orders.
